2017-06-26 17:30:43 ERROR (SyncWorker_5) [homeassistant.components.conversation] Unable to process: 
2017-06-26 17:30:47 ERROR (SyncWorker_7) [homeassistant.components.conversation] Unable to process: cern cooling on
2017-06-26 17:31:01 ERROR (SyncWorker_2) [homeassistant.components.conversation] Unable to process: 
2017-06-26 17:31:03 ERROR (SyncWorker_0) [homeassistant.components.conversation] Unable to process: 
2017-06-26 17:31:05 ERROR (SyncWorker_4) [homeassistant.components.conversation] Unable to process: 
2017-06-26 17:31:08 ERROR (SyncWorker_1) [homeassistant.components.conversation] Unable to process: cern cooling off
2017-06-26 17:31:11 ERROR (SyncWorker_2) [homeassistant.components.conversation] Unable to process: 
2017-06-26 17:34:38 ERROR (SyncWorker_0) [homeassistant.components.conversation] Unable to process: 
2017-06-26 17:35:06 ERROR (SyncWorker_2) [homeassistant.components.conversation] Got unsupported command auf from text turn party mode auf
2017-06-26 17:48:18 ERROR (SyncWorker_8) [homeassistant.components.conversation] Got unsupported command an from text turn romantik an
2017-06-26 17:48:20 ERROR (SyncWorker_7) [homeassistant.components.conversation] Unable to process: 
2017-06-26 17:48:25 ERROR (SyncWorker_2) [homeassistant.components.conversation] Got unsupported command an from text turn romantik an
2017-06-26 17:48:44 ERROR (SyncWorker_0) [homeassistant.components.conversation] Unable to process: turn romantika
2017-06-26 17:54:15 WARNING (MainThread) [homeassistant.helpers.entity] Update of media_player.spotify is taking over 10 seconds
2017-06-26 17:54:35 WARNING (MainThread) [homeassistant.components.media_player] Updating spotify media_player took longer than the scheduled update interval 0:00:30
2017-06-26 17:55:06 WARNING (MainThread) [homeassistant.components.media_player] Updating spotify media_player took longer than the scheduled update interval 0:00:30
2017-06-26 17:55:12 ERROR (MainThread) [homeassistant.core] Error doing job: Fatal read error on socket transport
Traceback (most recent call last):
  File "/usr/local/Cellar/python3/3.6.1/Frameworks/Python.framework/Versions/3.6/lib/python3.6/asyncio/selector_events.py", line 724, in _read_ready
    data = self._sock.recv(self.max_size)
TimeoutError: [Errno 60] Operation timed out
2017-06-26 17:55:36 WARNING (MainThread) [homeassistant.components.media_player] Updating spotify media_player took longer than the scheduled update interval 0:00:30
2017-06-26 17:56:07 WARNING (MainThread) [homeassistant.components.media_player] Updating spotify media_player took longer than the scheduled update interval 0:00:30
2017-06-26 17:56:38 WARNING (MainThread) [homeassistant.components.media_player] Updating spotify media_player took longer than the scheduled update interval 0:00:30
2017-06-26 17:57:09 WARNING (MainThread) [homeassistant.components.media_player] Updating spotify media_player took longer than the scheduled update interval 0:00:30
2017-06-26 17:57:28 WARNING (MainThread) [homeassistant.helpers.entity] Update for media_player.spotify is already in progress
2017-06-26 17:57:37 WARNING (MainThread) [homeassistant.helpers.entity] Update for media_player.spotify is already in progress
2017-06-26 17:57:40 WARNING (MainThread) [homeassistant.components.media_player] Updating spotify media_player took longer than the scheduled update interval 0:00:30
2017-06-26 17:57:41 WARNING (MainThread) [homeassistant.helpers.entity] Update for media_player.spotify is already in progress
2017-06-26 17:57:51 WARNING (MainThread) [homeassistant.helpers.entity] Update for media_player.spotify is already in progress
2017-06-26 17:57:57 WARNING (MainThread) [homeassistant.helpers.entity] Update for media_player.spotify is already in progress
2017-06-26 17:57:59 WARNING (MainThread) [homeassistant.helpers.entity] Update for media_player.spotify is already in progress
2017-06-26 17:58:02 WARNING (MainThread) [homeassistant.helpers.entity] Update for media_player.spotify is already in progress
2017-06-26 17:58:11 WARNING (MainThread) [homeassistant.components.media_player] Updating spotify media_player took longer than the scheduled update interval 0:00:30
2017-06-26 17:58:13 ERROR (SyncWorker_3) [homeassistant.components.conversation] Unable to process: turn hip-hop mode on
2017-06-26 17:58:24 WARNING (MainThread) [homeassistant.helpers.entity] Update for media_player.spotify is already in progress
2017-06-26 17:58:32 WARNING (MainThread) [homeassistant.helpers.entity] Update for media_player.spotify is already in progress
2017-06-26 17:58:42 WARNING (MainThread) [homeassistant.components.media_player] Updating spotify media_player took longer than the scheduled update interval 0:00:30
2017-06-26 17:59:13 WARNING (MainThread) [homeassistant.components.media_player] Updating spotify media_player took longer than the scheduled update interval 0:00:30
2017-06-26 17:59:44 WARNING (MainThread) [homeassistant.components.media_player] Updating spotify media_player took longer than the scheduled update interval 0:00:30
2017-06-26 18:00:14 WARNING (MainThread) [homeassistant.components.media_player] Updating spotify media_player took longer than the scheduled update interval 0:00:30
2017-06-26 18:00:36 ERROR (SyncWorker_2) [homeassistant.components.conversation] Unable to process: 
2017-06-26 18:00:45 WARNING (MainThread) [homeassistant.components.media_player] Updating spotify media_player took longer than the scheduled update interval 0:00:30
2017-06-26 18:01:16 WARNING (MainThread) [homeassistant.components.media_player] Updating spotify media_player took longer than the scheduled update interval 0:00:30
2017-06-26 18:01:23 WARNING (MainThread) [homeassistant.helpers.entity] Update for media_player.spotify is already in progress
2017-06-26 18:01:46 WARNING (MainThread) [homeassistant.components.media_player] Updating spotify media_player took longer than the scheduled update interval 0:00:30
2017-06-26 18:02:17 WARNING (MainThread) [homeassistant.components.media_player] Updating spotify media_player took longer than the scheduled update interval 0:00:30
2017-06-26 18:02:47 WARNING (MainThread) [homeassistant.components.media_player] Updating spotify media_player took longer than the scheduled update interval 0:00:30
2017-06-26 18:03:18 WARNING (MainThread) [homeassistant.components.media_player] Updating spotify media_player took longer than the scheduled update interval 0:00:30
2017-06-26 18:03:49 WARNING (MainThread) [homeassistant.components.media_player] Updating spotify media_player took longer than the scheduled update interval 0:00:30
2017-06-26 18:04:20 WARNING (MainThread) [homeassistant.components.media_player] Updating spotify media_player took longer than the scheduled update interval 0:00:30
2017-06-26 18:04:51 WARNING (MainThread) [homeassistant.components.media_player] Updating spotify media_player took longer than the scheduled update interval 0:00:30
2017-06-26 18:05:22 WARNING (MainThread) [homeassistant.components.media_player] Updating spotify media_player took longer than the scheduled update interval 0:00:30
2017-06-26 18:05:52 WARNING (MainThread) [homeassistant.components.media_player] Updating spotify media_player took longer than the scheduled update interval 0:00:30
2017-06-26 18:06:23 WARNING (MainThread) [homeassistant.components.media_player] Updating spotify media_player took longer than the scheduled update interval 0:00:30
2017-06-26 18:06:54 WARNING (MainThread) [homeassistant.components.media_player] Updating spotify media_player took longer than the scheduled update interval 0:00:30
2017-06-26 18:07:25 WARNING (MainThread) [homeassistant.components.media_player] Updating spotify media_player took longer than the scheduled update interval 0:00:30
2017-06-26 18:07:28 ERROR (MainThread) [homeassistant.core] Error doing job: Fatal read error on socket transport
Traceback (most recent call last):
  File "/usr/local/Cellar/python3/3.6.1/Frameworks/Python.framework/Versions/3.6/lib/python3.6/asyncio/selector_events.py", line 724, in _read_ready
    data = self._sock.recv(self.max_size)
TimeoutError: [Errno 60] Operation timed out
2017-06-26 18:07:56 WARNING (MainThread) [homeassistant.components.media_player] Updating spotify media_player took longer than the scheduled update interval 0:00:30
2017-06-26 18:08:27 WARNING (MainThread) [homeassistant.components.media_player] Updating spotify media_player took longer than the scheduled update interval 0:00:30
2017-06-26 18:08:58 WARNING (MainThread) [homeassistant.components.media_player] Updating spotify media_player took longer than the scheduled update interval 0:00:30
2017-06-26 18:09:02 ERROR (MainThread) [homeassistant.helpers.entity] Update for media_player.spotify fails
Traceback (most recent call last):
  File "/usr/local/lib/python3.6/site-packages/urllib3/connectionpool.py", line 600, in urlopen
    chunked=chunked)
  File "/usr/local/lib/python3.6/site-packages/urllib3/connectionpool.py", line 345, in _make_request
    self._validate_conn(conn)
  File "/usr/local/lib/python3.6/site-packages/urllib3/connectionpool.py", line 844, in _validate_conn
    conn.connect()
  File "/usr/local/lib/python3.6/site-packages/urllib3/connection.py", line 326, in connect
    ssl_context=context)
  File "/usr/local/lib/python3.6/site-packages/urllib3/util/ssl_.py", line 325, in ssl_wrap_socket
    return context.wrap_socket(sock, server_hostname=server_hostname)
  File "/usr/local/Cellar/python3/3.6.1/Frameworks/Python.framework/Versions/3.6/lib/python3.6/ssl.py", line 401, in wrap_socket
    _context=self, _session=session)
  File "/usr/local/Cellar/python3/3.6.1/Frameworks/Python.framework/Versions/3.6/lib/python3.6/ssl.py", line 808, in __init__
    self.do_handshake()
  File "/usr/local/Cellar/python3/3.6.1/Frameworks/Python.framework/Versions/3.6/lib/python3.6/ssl.py", line 1061, in do_handshake
    self._sslobj.do_handshake()
  File "/usr/local/Cellar/python3/3.6.1/Frameworks/Python.framework/Versions/3.6/lib/python3.6/ssl.py", line 683, in do_handshake
    self._sslobj.do_handshake()
TimeoutError: [Errno 60] Operation timed out

During handling of the above exception, another exception occurred:

Traceback (most recent call last):
  File "/usr/local/lib/python3.6/site-packages/requests/adapters.py", line 440, in send
    timeout=timeout
  File "/usr/local/lib/python3.6/site-packages/urllib3/connectionpool.py", line 649, in urlopen
    _stacktrace=sys.exc_info()[2])
  File "/usr/local/lib/python3.6/site-packages/urllib3/util/retry.py", line 357, in increment
    raise six.reraise(type(error), error, _stacktrace)
  File "/usr/local/lib/python3.6/site-packages/urllib3/packages/six.py", line 685, in reraise
    raise value.with_traceback(tb)
  File "/usr/local/lib/python3.6/site-packages/urllib3/connectionpool.py", line 600, in urlopen
    chunked=chunked)
  File "/usr/local/lib/python3.6/site-packages/urllib3/connectionpool.py", line 345, in _make_request
    self._validate_conn(conn)
  File "/usr/local/lib/python3.6/site-packages/urllib3/connectionpool.py", line 844, in _validate_conn
    conn.connect()
  File "/usr/local/lib/python3.6/site-packages/urllib3/connection.py", line 326, in connect
    ssl_context=context)
  File "/usr/local/lib/python3.6/site-packages/urllib3/util/ssl_.py", line 325, in ssl_wrap_socket
    return context.wrap_socket(sock, server_hostname=server_hostname)
  File "/usr/local/Cellar/python3/3.6.1/Frameworks/Python.framework/Versions/3.6/lib/python3.6/ssl.py", line 401, in wrap_socket
    _context=self, _session=session)
  File "/usr/local/Cellar/python3/3.6.1/Frameworks/Python.framework/Versions/3.6/lib/python3.6/ssl.py", line 808, in __init__
    self.do_handshake()
  File "/usr/local/Cellar/python3/3.6.1/Frameworks/Python.framework/Versions/3.6/lib/python3.6/ssl.py", line 1061, in do_handshake
    self._sslobj.do_handshake()
  File "/usr/local/Cellar/python3/3.6.1/Frameworks/Python.framework/Versions/3.6/lib/python3.6/ssl.py", line 683, in do_handshake
    self._sslobj.do_handshake()
urllib3.exceptions.ProtocolError: ('Connection aborted.', TimeoutError(60, 'Operation timed out'))

During handling of the above exception, another exception occurred:

Traceback (most recent call last):
  File "/usr/local/lib/python3.6/site-packages/homeassistant/helpers/entity.py", line 224, in async_update_ha_state
    yield from self.hass.async_add_job(self.update)
  File "/usr/local/Cellar/python3/3.6.1/Frameworks/Python.framework/Versions/3.6/lib/python3.6/asyncio/futures.py", line 331, in __iter__
    yield self  # This tells Task to wait for completion.
  File "/usr/local/Cellar/python3/3.6.1/Frameworks/Python.framework/Versions/3.6/lib/python3.6/asyncio/tasks.py", line 244, in _wakeup
    future.result()
  File "/usr/local/Cellar/python3/3.6.1/Frameworks/Python.framework/Versions/3.6/lib/python3.6/asyncio/futures.py", line 244, in result
    raise self._exception
  File "/usr/local/Cellar/python3/3.6.1/Frameworks/Python.framework/Versions/3.6/lib/python3.6/concurrent/futures/thread.py", line 55, in run
    result = self.fn(*self.args, **self.kwargs)
  File "/usr/local/lib/python3.6/site-packages/homeassistant/components/media_player/spotify.py", line 177, in update
    current = self._player.current_playback()
  File "/usr/local/lib/python3.6/site-packages/spotipy/client.py", line 856, in current_playback
    return self._get("me/player", market = market)
  File "/usr/local/lib/python3.6/site-packages/spotipy/client.py", line 148, in _get
    return self._internal_call('GET', url, payload, kwargs)
  File "/usr/local/lib/python3.6/site-packages/spotipy/client.py", line 110, in _internal_call
    r = self._session.request(method, url, headers=headers, proxies=self.proxies, **args)
  File "/usr/local/lib/python3.6/site-packages/requests/sessions.py", line 502, in request
    resp = self.send(prep, **send_kwargs)
  File "/usr/local/lib/python3.6/site-packages/requests/sessions.py", line 612, in send
    r = adapter.send(request, **kwargs)
  File "/usr/local/lib/python3.6/site-packages/requests/adapters.py", line 490, in send
    raise ConnectionError(err, request=request)
requests.exceptions.ConnectionError: ('Connection aborted.', TimeoutError(60, 'Operation timed out'))
2017-06-26 18:17:39 WARNING (Thread-2) [homeassistant.components.mqtt] Disconnected from MQTT (1). Trying to reconnect in 1 s
2017-06-26 18:25:59 ERROR (SyncWorker_1) [homeassistant.components.conversation] Unable to process: 
2017-06-26 18:27:35 ERROR (MainThread) [homeassistant.helpers.entity] Update for media_player.spotify fails
Traceback (most recent call last):
  File "/usr/local/lib/python3.6/site-packages/urllib3/connection.py", line 141, in _new_conn
    (self.host, self.port), self.timeout, **extra_kw)
  File "/usr/local/lib/python3.6/site-packages/urllib3/util/connection.py", line 60, in create_connection
    for res in socket.getaddrinfo(host, port, family, socket.SOCK_STREAM):
  File "/usr/local/Cellar/python3/3.6.1/Frameworks/Python.framework/Versions/3.6/lib/python3.6/socket.py", line 743, in getaddrinfo
    for res in _socket.getaddrinfo(host, port, family, type, proto, flags):
socket.gaierror: [Errno 8] nodename nor servname provided, or not known

During handling of the above exception, another exception occurred:

Traceback (most recent call last):
  File "/usr/local/lib/python3.6/site-packages/urllib3/connectionpool.py", line 600, in urlopen
    chunked=chunked)
  File "/usr/local/lib/python3.6/site-packages/urllib3/connectionpool.py", line 345, in _make_request
    self._validate_conn(conn)
  File "/usr/local/lib/python3.6/site-packages/urllib3/connectionpool.py", line 844, in _validate_conn
    conn.connect()
  File "/usr/local/lib/python3.6/site-packages/urllib3/connection.py", line 284, in connect
    conn = self._new_conn()
  File "/usr/local/lib/python3.6/site-packages/urllib3/connection.py", line 150, in _new_conn
    self, "Failed to establish a new connection: %s" % e)
urllib3.exceptions.NewConnectionError: <urllib3.connection.VerifiedHTTPSConnection object at 0x10753bac8>: Failed to establish a new connection: [Errno 8] nodename nor servname provided, or not known

During handling of the above exception, another exception occurred:

Traceback (most recent call last):
  File "/usr/local/lib/python3.6/site-packages/requests/adapters.py", line 440, in send
    timeout=timeout
  File "/usr/local/lib/python3.6/site-packages/urllib3/connectionpool.py", line 649, in urlopen
    _stacktrace=sys.exc_info()[2])
  File "/usr/local/lib/python3.6/site-packages/urllib3/util/retry.py", line 388, in increment
    raise MaxRetryError(_pool, url, error or ResponseError(cause))
urllib3.exceptions.MaxRetryError: HTTPSConnectionPool(host='api.spotify.com', port=443): Max retries exceeded with url: /v1/me/player/devices (Caused by NewConnectionError('<urllib3.connection.VerifiedHTTPSConnection object at 0x10753bac8>: Failed to establish a new connection: [Errno 8] nodename nor servname provided, or not known',))

During handling of the above exception, another exception occurred:

Traceback (most recent call last):
  File "/usr/local/lib/python3.6/site-packages/homeassistant/helpers/entity.py", line 224, in async_update_ha_state
    yield from self.hass.async_add_job(self.update)
  File "/usr/local/Cellar/python3/3.6.1/Frameworks/Python.framework/Versions/3.6/lib/python3.6/asyncio/futures.py", line 331, in __iter__
    yield self  # This tells Task to wait for completion.
  File "/usr/local/Cellar/python3/3.6.1/Frameworks/Python.framework/Versions/3.6/lib/python3.6/asyncio/tasks.py", line 244, in _wakeup
    future.result()
  File "/usr/local/Cellar/python3/3.6.1/Frameworks/Python.framework/Versions/3.6/lib/python3.6/asyncio/futures.py", line 244, in result
    raise self._exception
  File "/usr/local/Cellar/python3/3.6.1/Frameworks/Python.framework/Versions/3.6/lib/python3.6/concurrent/futures/thread.py", line 55, in run
    result = self.fn(*self.args, **self.kwargs)
  File "/usr/local/lib/python3.6/site-packages/homeassistant/components/media_player/spotify.py", line 163, in update
    player_devices = self._player.devices()
  File "/usr/local/lib/python3.6/site-packages/spotipy/client.py", line 848, in devices
    return self._get("me/player/devices")
  File "/usr/local/lib/python3.6/site-packages/spotipy/client.py", line 148, in _get
    return self._internal_call('GET', url, payload, kwargs)
  File "/usr/local/lib/python3.6/site-packages/spotipy/client.py", line 110, in _internal_call
    r = self._session.request(method, url, headers=headers, proxies=self.proxies, **args)
  File "/usr/local/lib/python3.6/site-packages/requests/sessions.py", line 502, in request
    resp = self.send(prep, **send_kwargs)
  File "/usr/local/lib/python3.6/site-packages/requests/sessions.py", line 612, in send
    r = adapter.send(request, **kwargs)
  File "/usr/local/lib/python3.6/site-packages/requests/adapters.py", line 504, in send
    raise ConnectionError(e, request=request)
requests.exceptions.ConnectionError: HTTPSConnectionPool(host='api.spotify.com', port=443): Max retries exceeded with url: /v1/me/player/devices (Caused by NewConnectionError('<urllib3.connection.VerifiedHTTPSConnection object at 0x10753bac8>: Failed to establish a new connection: [Errno 8] nodename nor servname provided, or not known',))
2017-06-26 18:28:03 ERROR (MainThread) [homeassistant.helpers.entity] Update for media_player.spotify fails
Traceback (most recent call last):
  File "/usr/local/lib/python3.6/site-packages/urllib3/connection.py", line 141, in _new_conn
    (self.host, self.port), self.timeout, **extra_kw)
  File "/usr/local/lib/python3.6/site-packages/urllib3/util/connection.py", line 60, in create_connection
    for res in socket.getaddrinfo(host, port, family, socket.SOCK_STREAM):
  File "/usr/local/Cellar/python3/3.6.1/Frameworks/Python.framework/Versions/3.6/lib/python3.6/socket.py", line 743, in getaddrinfo
    for res in _socket.getaddrinfo(host, port, family, type, proto, flags):
socket.gaierror: [Errno 8] nodename nor servname provided, or not known

During handling of the above exception, another exception occurred:

Traceback (most recent call last):
  File "/usr/local/lib/python3.6/site-packages/urllib3/connectionpool.py", line 600, in urlopen
    chunked=chunked)
  File "/usr/local/lib/python3.6/site-packages/urllib3/connectionpool.py", line 345, in _make_request
    self._validate_conn(conn)
  File "/usr/local/lib/python3.6/site-packages/urllib3/connectionpool.py", line 844, in _validate_conn
    conn.connect()
  File "/usr/local/lib/python3.6/site-packages/urllib3/connection.py", line 284, in connect
    conn = self._new_conn()
  File "/usr/local/lib/python3.6/site-packages/urllib3/connection.py", line 150, in _new_conn
    self, "Failed to establish a new connection: %s" % e)
urllib3.exceptions.NewConnectionError: <urllib3.connection.VerifiedHTTPSConnection object at 0x10752e7b8>: Failed to establish a new connection: [Errno 8] nodename nor servname provided, or not known

During handling of the above exception, another exception occurred:

Traceback (most recent call last):
  File "/usr/local/lib/python3.6/site-packages/requests/adapters.py", line 440, in send
    timeout=timeout
  File "/usr/local/lib/python3.6/site-packages/urllib3/connectionpool.py", line 649, in urlopen
    _stacktrace=sys.exc_info()[2])
  File "/usr/local/lib/python3.6/site-packages/urllib3/util/retry.py", line 388, in increment
    raise MaxRetryError(_pool, url, error or ResponseError(cause))
urllib3.exceptions.MaxRetryError: HTTPSConnectionPool(host='api.spotify.com', port=443): Max retries exceeded with url: /v1/me/player/devices (Caused by NewConnectionError('<urllib3.connection.VerifiedHTTPSConnection object at 0x10752e7b8>: Failed to establish a new connection: [Errno 8] nodename nor servname provided, or not known',))

During handling of the above exception, another exception occurred:

Traceback (most recent call last):
  File "/usr/local/lib/python3.6/site-packages/homeassistant/helpers/entity.py", line 224, in async_update_ha_state
    yield from self.hass.async_add_job(self.update)
  File "/usr/local/Cellar/python3/3.6.1/Frameworks/Python.framework/Versions/3.6/lib/python3.6/asyncio/futures.py", line 331, in __iter__
    yield self  # This tells Task to wait for completion.
  File "/usr/local/Cellar/python3/3.6.1/Frameworks/Python.framework/Versions/3.6/lib/python3.6/asyncio/tasks.py", line 244, in _wakeup
    future.result()
  File "/usr/local/Cellar/python3/3.6.1/Frameworks/Python.framework/Versions/3.6/lib/python3.6/asyncio/futures.py", line 244, in result
    raise self._exception
  File "/usr/local/Cellar/python3/3.6.1/Frameworks/Python.framework/Versions/3.6/lib/python3.6/concurrent/futures/thread.py", line 55, in run
    result = self.fn(*self.args, **self.kwargs)
  File "/usr/local/lib/python3.6/site-packages/homeassistant/components/media_player/spotify.py", line 163, in update
    player_devices = self._player.devices()
  File "/usr/local/lib/python3.6/site-packages/spotipy/client.py", line 848, in devices
    return self._get("me/player/devices")
  File "/usr/local/lib/python3.6/site-packages/spotipy/client.py", line 148, in _get
    return self._internal_call('GET', url, payload, kwargs)
  File "/usr/local/lib/python3.6/site-packages/spotipy/client.py", line 110, in _internal_call
    r = self._session.request(method, url, headers=headers, proxies=self.proxies, **args)
  File "/usr/local/lib/python3.6/site-packages/requests/sessions.py", line 502, in request
    resp = self.send(prep, **send_kwargs)
  File "/usr/local/lib/python3.6/site-packages/requests/sessions.py", line 612, in send
    r = adapter.send(request, **kwargs)
  File "/usr/local/lib/python3.6/site-packages/requests/adapters.py", line 504, in send
    raise ConnectionError(e, request=request)
requests.exceptions.ConnectionError: HTTPSConnectionPool(host='api.spotify.com', port=443): Max retries exceeded with url: /v1/me/player/devices (Caused by NewConnectionError('<urllib3.connection.VerifiedHTTPSConnection object at 0x10752e7b8>: Failed to establish a new connection: [Errno 8] nodename nor servname provided, or not known',))
2017-06-26 18:28:24 ERROR (MainThread) [homeassistant.core] Error doing job: Fatal read error on socket transport
Traceback (most recent call last):
  File "/usr/local/Cellar/python3/3.6.1/Frameworks/Python.framework/Versions/3.6/lib/python3.6/asyncio/selector_events.py", line 724, in _read_ready
    data = self._sock.recv(self.max_size)
TimeoutError: [Errno 60] Operation timed out
2017-06-26 18:28:24 ERROR (MainThread) [homeassistant.core] Error doing job: Fatal read error on socket transport
Traceback (most recent call last):
  File "/usr/local/Cellar/python3/3.6.1/Frameworks/Python.framework/Versions/3.6/lib/python3.6/asyncio/selector_events.py", line 724, in _read_ready
    data = self._sock.recv(self.max_size)
TimeoutError: [Errno 60] Operation timed out
2017-06-26 18:28:36 ERROR (MainThread) [homeassistant.helpers.entity] Update for media_player.spotify fails
Traceback (most recent call last):
  File "/usr/local/lib/python3.6/site-packages/urllib3/connection.py", line 141, in _new_conn
    (self.host, self.port), self.timeout, **extra_kw)
  File "/usr/local/lib/python3.6/site-packages/urllib3/util/connection.py", line 60, in create_connection
    for res in socket.getaddrinfo(host, port, family, socket.SOCK_STREAM):
  File "/usr/local/Cellar/python3/3.6.1/Frameworks/Python.framework/Versions/3.6/lib/python3.6/socket.py", line 743, in getaddrinfo
    for res in _socket.getaddrinfo(host, port, family, type, proto, flags):
socket.gaierror: [Errno 8] nodename nor servname provided, or not known

During handling of the above exception, another exception occurred:

Traceback (most recent call last):
  File "/usr/local/lib/python3.6/site-packages/urllib3/connectionpool.py", line 600, in urlopen
    chunked=chunked)
  File "/usr/local/lib/python3.6/site-packages/urllib3/connectionpool.py", line 345, in _make_request
    self._validate_conn(conn)
  File "/usr/local/lib/python3.6/site-packages/urllib3/connectionpool.py", line 844, in _validate_conn
    conn.connect()
  File "/usr/local/lib/python3.6/site-packages/urllib3/connection.py", line 284, in connect
    conn = self._new_conn()
  File "/usr/local/lib/python3.6/site-packages/urllib3/connection.py", line 150, in _new_conn
    self, "Failed to establish a new connection: %s" % e)
urllib3.exceptions.NewConnectionError: <urllib3.connection.VerifiedHTTPSConnection object at 0x10753b080>: Failed to establish a new connection: [Errno 8] nodename nor servname provided, or not known

During handling of the above exception, another exception occurred:

Traceback (most recent call last):
  File "/usr/local/lib/python3.6/site-packages/requests/adapters.py", line 440, in send
    timeout=timeout
  File "/usr/local/lib/python3.6/site-packages/urllib3/connectionpool.py", line 649, in urlopen
    _stacktrace=sys.exc_info()[2])
  File "/usr/local/lib/python3.6/site-packages/urllib3/util/retry.py", line 388, in increment
    raise MaxRetryError(_pool, url, error or ResponseError(cause))
urllib3.exceptions.MaxRetryError: HTTPSConnectionPool(host='api.spotify.com', port=443): Max retries exceeded with url: /v1/me/player/devices (Caused by NewConnectionError('<urllib3.connection.VerifiedHTTPSConnection object at 0x10753b080>: Failed to establish a new connection: [Errno 8] nodename nor servname provided, or not known',))

During handling of the above exception, another exception occurred:

Traceback (most recent call last):
  File "/usr/local/lib/python3.6/site-packages/homeassistant/helpers/entity.py", line 224, in async_update_ha_state
    yield from self.hass.async_add_job(self.update)
  File "/usr/local/Cellar/python3/3.6.1/Frameworks/Python.framework/Versions/3.6/lib/python3.6/asyncio/futures.py", line 331, in __iter__
    yield self  # This tells Task to wait for completion.
  File "/usr/local/Cellar/python3/3.6.1/Frameworks/Python.framework/Versions/3.6/lib/python3.6/asyncio/tasks.py", line 244, in _wakeup
    future.result()
  File "/usr/local/Cellar/python3/3.6.1/Frameworks/Python.framework/Versions/3.6/lib/python3.6/asyncio/futures.py", line 244, in result
    raise self._exception
  File "/usr/local/Cellar/python3/3.6.1/Frameworks/Python.framework/Versions/3.6/lib/python3.6/concurrent/futures/thread.py", line 55, in run
    result = self.fn(*self.args, **self.kwargs)
  File "/usr/local/lib/python3.6/site-packages/homeassistant/components/media_player/spotify.py", line 163, in update
    player_devices = self._player.devices()
  File "/usr/local/lib/python3.6/site-packages/spotipy/client.py", line 848, in devices
    return self._get("me/player/devices")
  File "/usr/local/lib/python3.6/site-packages/spotipy/client.py", line 148, in _get
    return self._internal_call('GET', url, payload, kwargs)
  File "/usr/local/lib/python3.6/site-packages/spotipy/client.py", line 110, in _internal_call
    r = self._session.request(method, url, headers=headers, proxies=self.proxies, **args)
  File "/usr/local/lib/python3.6/site-packages/requests/sessions.py", line 502, in request
    resp = self.send(prep, **send_kwargs)
  File "/usr/local/lib/python3.6/site-packages/requests/sessions.py", line 612, in send
    r = adapter.send(request, **kwargs)
  File "/usr/local/lib/python3.6/site-packages/requests/adapters.py", line 504, in send
    raise ConnectionError(e, request=request)
requests.exceptions.ConnectionError: HTTPSConnectionPool(host='api.spotify.com', port=443): Max retries exceeded with url: /v1/me/player/devices (Caused by NewConnectionError('<urllib3.connection.VerifiedHTTPSConnection object at 0x10753b080>: Failed to establish a new connection: [Errno 8] nodename nor servname provided, or not known',))
2017-06-26 18:29:05 ERROR (MainThread) [homeassistant.helpers.entity] Update for media_player.spotify fails
Traceback (most recent call last):
  File "/usr/local/lib/python3.6/site-packages/urllib3/connection.py", line 141, in _new_conn
    (self.host, self.port), self.timeout, **extra_kw)
  File "/usr/local/lib/python3.6/site-packages/urllib3/util/connection.py", line 60, in create_connection
    for res in socket.getaddrinfo(host, port, family, socket.SOCK_STREAM):
  File "/usr/local/Cellar/python3/3.6.1/Frameworks/Python.framework/Versions/3.6/lib/python3.6/socket.py", line 743, in getaddrinfo
    for res in _socket.getaddrinfo(host, port, family, type, proto, flags):
socket.gaierror: [Errno 8] nodename nor servname provided, or not known

During handling of the above exception, another exception occurred:

Traceback (most recent call last):
  File "/usr/local/lib/python3.6/site-packages/urllib3/connectionpool.py", line 600, in urlopen
    chunked=chunked)
  File "/usr/local/lib/python3.6/site-packages/urllib3/connectionpool.py", line 345, in _make_request
    self._validate_conn(conn)
  File "/usr/local/lib/python3.6/site-packages/urllib3/connectionpool.py", line 844, in _validate_conn
    conn.connect()
  File "/usr/local/lib/python3.6/site-packages/urllib3/connection.py", line 284, in connect
    conn = self._new_conn()
  File "/usr/local/lib/python3.6/site-packages/urllib3/connection.py", line 150, in _new_conn
    self, "Failed to establish a new connection: %s" % e)
urllib3.exceptions.NewConnectionError: <urllib3.connection.VerifiedHTTPSConnection object at 0x107537898>: Failed to establish a new connection: [Errno 8] nodename nor servname provided, or not known

During handling of the above exception, another exception occurred:

Traceback (most recent call last):
  File "/usr/local/lib/python3.6/site-packages/requests/adapters.py", line 440, in send
    timeout=timeout
  File "/usr/local/lib/python3.6/site-packages/urllib3/connectionpool.py", line 649, in urlopen
    _stacktrace=sys.exc_info()[2])
  File "/usr/local/lib/python3.6/site-packages/urllib3/util/retry.py", line 388, in increment
    raise MaxRetryError(_pool, url, error or ResponseError(cause))
urllib3.exceptions.MaxRetryError: HTTPSConnectionPool(host='api.spotify.com', port=443): Max retries exceeded with url: /v1/me/player/devices (Caused by NewConnectionError('<urllib3.connection.VerifiedHTTPSConnection object at 0x107537898>: Failed to establish a new connection: [Errno 8] nodename nor servname provided, or not known',))

During handling of the above exception, another exception occurred:

Traceback (most recent call last):
  File "/usr/local/lib/python3.6/site-packages/homeassistant/helpers/entity.py", line 224, in async_update_ha_state
    yield from self.hass.async_add_job(self.update)
  File "/usr/local/Cellar/python3/3.6.1/Frameworks/Python.framework/Versions/3.6/lib/python3.6/asyncio/futures.py", line 331, in __iter__
    yield self  # This tells Task to wait for completion.
  File "/usr/local/Cellar/python3/3.6.1/Frameworks/Python.framework/Versions/3.6/lib/python3.6/asyncio/tasks.py", line 244, in _wakeup
    future.result()
  File "/usr/local/Cellar/python3/3.6.1/Frameworks/Python.framework/Versions/3.6/lib/python3.6/asyncio/futures.py", line 244, in result
    raise self._exception
  File "/usr/local/Cellar/python3/3.6.1/Frameworks/Python.framework/Versions/3.6/lib/python3.6/concurrent/futures/thread.py", line 55, in run
    result = self.fn(*self.args, **self.kwargs)
  File "/usr/local/lib/python3.6/site-packages/homeassistant/components/media_player/spotify.py", line 163, in update
    player_devices = self._player.devices()
  File "/usr/local/lib/python3.6/site-packages/spotipy/client.py", line 848, in devices
    return self._get("me/player/devices")
  File "/usr/local/lib/python3.6/site-packages/spotipy/client.py", line 148, in _get
    return self._internal_call('GET', url, payload, kwargs)
  File "/usr/local/lib/python3.6/site-packages/spotipy/client.py", line 110, in _internal_call
    r = self._session.request(method, url, headers=headers, proxies=self.proxies, **args)
  File "/usr/local/lib/python3.6/site-packages/requests/sessions.py", line 502, in request
    resp = self.send(prep, **send_kwargs)
  File "/usr/local/lib/python3.6/site-packages/requests/sessions.py", line 612, in send
    r = adapter.send(request, **kwargs)
  File "/usr/local/lib/python3.6/site-packages/requests/adapters.py", line 504, in send
    raise ConnectionError(e, request=request)
requests.exceptions.ConnectionError: HTTPSConnectionPool(host='api.spotify.com', port=443): Max retries exceeded with url: /v1/me/player/devices (Caused by NewConnectionError('<urllib3.connection.VerifiedHTTPSConnection object at 0x107537898>: Failed to establish a new connection: [Errno 8] nodename nor servname provided, or not known',))
2017-06-26 18:40:34 WARNING (Thread-2) [homeassistant.components.mqtt] Disconnected from MQTT (1). Trying to reconnect in 1 s
2017-06-26 18:42:45 ERROR (SyncWorker_8) [homeassistant.components.conversation] Unable to process: 
2017-06-26 18:43:43 ERROR (SyncWorker_4) [homeassistant.components.conversation] Unable to process: 
2017-06-26 18:45:00 WARNING (MainThread) [homeassistant.helpers.entity] Update for media_player.spotify is already in progress
2017-06-26 18:52:14 ERROR (SyncWorker_3) [homeassistant.components.conversation] Unable to process: jana manticon
2017-06-26 18:58:01 WARNING (MainThread) [homeassistant.components.media_player] Updating spotify media_player took longer than the scheduled update interval 0:00:30
2017-06-26 18:58:13 WARNING (MainThread) [homeassistant.helpers.entity] Update of media_player.spotify is taking over 10 seconds
